<?xml version="1.0" encoding="UTF-8"?>
<!-- Generated by org.testng.reporters.JUnitReportReporter -->
<testsuite hostname="Ilamaran" name="com.gpom.testcasespackage.Testcases" tests="1" failures="0" timestamp="29 Jul 2017 15:58:02 GMT" time="15.758" errors="1">
  <testcase name="googleTest" time="15.758" classname="com.gpom.testcasespackage.Testcases">
    <error type="java.lang.AssertionError" message="expected:&lt;zadaniem testu&gt; but was:&lt;Luksusowe zadanie testowe&gt;">
      <![CDATA[java.lang.AssertionError: expected:<zadaniem testu> but was:<Luksusowe zadanie testowe>
	at org.testng.Assert.fail(Assert.java:89)
	at org.testng.Assert.failNotEquals(Assert.java:489)
	at org.testng.Assert.assertEquals(Assert.java:118)
	at org.testng.Assert.assertEquals(Assert.java:171)
	at org.testng.Assert.assertEquals(Assert.java:181)
	at com.gpom.gproject.googlepages.Translatepage.enterText(Translatepage.java:72)
	at com.gpom.testcasespackage.Testcases.googleTest(Testcases.java:37)
	at sun.reflect.NativeMethodAccessorImpl.invoke0(Native Method)
	at sun.reflect.NativeMethodAccessorImpl.invoke(NativeMethodAccessorImpl.java:62)
	at sun.reflect.DelegatingMethodAccessorImpl.invoke(DelegatingMethodAccessorImpl.java:43)
	at java.lang.reflect.Method.invoke(Method.java:483)
	at org.testng.internal.MethodInvocationHelper.invokeMethod(MethodInvocationHelper.java:80)
	at org.testng.internal.Invoker.invokeMethod(Invoker.java:673)
	at org.testng.internal.Invoker.invokeTestMethod(Invoker.java:842)
	at org.testng.internal.Invoker.invokeTestMethods(Invoker.java:1166)
	at org.testng.internal.TestMethodWorker.invokeTestMethods(TestMethodWorker.java:125)
	at org.testng.internal.TestMethodWorker.run(TestMethodWorker.java:109)
	at org.testng.TestRunner.runWorkers(TestRunner.java:1178)
	at org.testng.TestRunner.privateRun(TestRunner.java:757)
	at org.testng.TestRunner.run(TestRunner.java:608)
	at org.testng.SuiteRunner.runTest(SuiteRunner.java:334)
	at org.testng.SuiteRunner.runSequentially(SuiteRunner.java:329)
	at org.testng.SuiteRunner.privateRun(SuiteRunner.java:291)
	at org.testng.SuiteRunner.run(SuiteRunner.java:240)
	at org.testng.SuiteRunnerWorker.runSuite(SuiteRunnerWorker.java:52)
	at org.testng.SuiteRunnerWorker.run(SuiteRunnerWorker.java:86)
	at org.testng.TestNG.runSuitesSequentially(TestNG.java:1158)
	at org.testng.TestNG.runSuitesLocally(TestNG.java:1083)
	at org.testng.TestNG.run(TestNG.java:999)
	at org.apache.maven.surefire.testng.TestNGExecutor.run(TestNGExecutor.java:293)
	at org.apache.maven.surefire.testng.TestNGXmlTestSuite.execute(TestNGXmlTestSuite.java:84)
	at org.apache.maven.surefire.testng.TestNGProvider.invoke(TestNGProvider.java:91)
	at org.apache.maven.surefire.booter.ForkedBooter.invokeProviderInSameClassLoader(ForkedBooter.java:200)
	at org.apache.maven.surefire.booter.ForkedBooter.runSuitesInProcess(ForkedBooter.java:153)
	at org.apache.maven.surefire.booter.ForkedBooter.main(ForkedBooter.java:103)
]]>
    </error>
  </testcase>
</testsuite>
